[2023-11-26T23:21:02.347+0000] {logging_mixin.py:154} INFO - Changing /opt/***/logs/dag_id=outcomes_dag/run_id=manual__2023-11-26T23:21:00.593417+00:00/task_id=extract permission to 509
[2023-11-26T23:21:02.373+0000] {logging_mixin.py:154} INFO - Changing /opt/***/logs/dag_id=outcomes_dag/run_id=manual__2023-11-26T23:21:00.593417+00:00/task_id=extract permission to 509
[2023-11-26T23:21:02.581+0000] {taskinstance.py:1159} INFO - Dependencies all met for dep_context=non-requeueable deps ti=<TaskInstance: outcomes_dag.extract manual__2023-11-26T23:21:00.593417+00:00 [queued]>
[2023-11-26T23:21:02.591+0000] {taskinstance.py:1159} INFO - Dependencies all met for dep_context=requeueable deps ti=<TaskInstance: outcomes_dag.extract manual__2023-11-26T23:21:00.593417+00:00 [queued]>
[2023-11-26T23:21:02.593+0000] {taskinstance.py:1361} INFO - Starting attempt 1 of 1
[2023-11-26T23:21:02.610+0000] {taskinstance.py:1382} INFO - Executing <Task(PythonOperator): extract> on 2023-11-26 23:21:00.593417+00:00
[2023-11-26T23:21:02.619+0000] {standard_task_runner.py:57} INFO - Started process 403 to run task
[2023-11-26T23:21:02.622+0000] {standard_task_runner.py:84} INFO - Running: ['***', 'tasks', 'run', 'outcomes_dag', 'extract', 'manual__2023-11-26T23:21:00.593417+00:00', '--job-id', '35', '--raw', '--subdir', 'DAGS_FOLDER/outcomes_dag.py', '--cfg-path', '/tmp/tmpl18_9hei']
[2023-11-26T23:21:02.632+0000] {standard_task_runner.py:85} INFO - Job 35: Subtask extract
[2023-11-26T23:21:02.713+0000] {logging_mixin.py:154} INFO - Changing /opt/***/logs/dag_id=outcomes_dag/run_id=manual__2023-11-26T23:21:00.593417+00:00/task_id=extract permission to 509
[2023-11-26T23:21:02.715+0000] {task_command.py:416} INFO - Running <TaskInstance: outcomes_dag.extract manual__2023-11-26T23:21:00.593417+00:00 [running]> on host 613ffde293d8
[2023-11-26T23:21:02.801+0000] {taskinstance.py:1662} INFO - Exporting env vars: AIRFLOW_CTX_DAG_OWNER='***' AIRFLOW_CTX_DAG_ID='outcomes_dag' AIRFLOW_CTX_TASK_ID='extract' AIRFLOW_CTX_EXECUTION_DATE='2023-11-26T23:21:00.593417+00:00' AIRFLOW_CTX_TRY_NUMBER='1' AIRFLOW_CTX_DAG_RUN_ID='manual__2023-11-26T23:21:00.593417+00:00'
[2023-11-26T23:21:12.284+0000] {taskinstance.py:1937} ERROR - Task failed with exception
Traceback (most recent call last):
  File "/home/airflow/.local/lib/python3.8/site-packages/urllib3/connectionpool.py", line 715, in urlopen
    httplib_response = self._make_request(
  File "/home/airflow/.local/lib/python3.8/site-packages/urllib3/connectionpool.py", line 467, in _make_request
    six.raise_from(e, None)
  File "<string>", line 3, in raise_from
  File "/home/airflow/.local/lib/python3.8/site-packages/urllib3/connectionpool.py", line 462, in _make_request
    httplib_response = conn.getresponse()
  File "/usr/local/lib/python3.8/http/client.py", line 1348, in getresponse
    response.begin()
  File "/usr/local/lib/python3.8/http/client.py", line 316, in begin
    version, status, reason = self._read_status()
  File "/usr/local/lib/python3.8/http/client.py", line 277, in _read_status
    line = str(self.fp.readline(_MAXLINE + 1), "iso-8859-1")
  File "/usr/local/lib/python3.8/socket.py", line 669, in readinto
    return self._sock.recv_into(b)
  File "/usr/local/lib/python3.8/ssl.py", line 1274, in recv_into
    return self.read(nbytes, buffer)
  File "/usr/local/lib/python3.8/ssl.py", line 1132, in read
    return self._sslobj.read(len, buffer)
ssl.SSLError: [SSL: SSLV3_ALERT_BAD_RECORD_MAC] sslv3 alert bad record mac (_ssl.c:2635)

During handling of the above exception, another exception occurred:

Traceback (most recent call last):
  File "/home/airflow/.local/lib/python3.8/site-packages/requests/adapters.py", line 486, in send
    resp = conn.urlopen(
  File "/home/airflow/.local/lib/python3.8/site-packages/urllib3/connectionpool.py", line 799, in urlopen
    retries = retries.increment(
  File "/home/airflow/.local/lib/python3.8/site-packages/urllib3/util/retry.py", line 592, in increment
    raise MaxRetryError(_pool, url, error or ResponseError(cause))
urllib3.exceptions.MaxRetryError: HTTPSConnectionPool(host='storage.googleapis.com', port=443): Max retries exceeded with url: /upload/storage/v1/b/raw_shelter_data_csv/o?uploadType=resumable&upload_id=ABPtcPob2Dqf1tbJG1LY2lz4swQQLRYMVOW2XTsKZE5brnU6zgidat6AYDKo8MNt3kJfqAy2H76CjhdOSeLboBAGJJk_uGq_klFY6eu7HUEaR3vm (Caused by SSLError(SSLError(1, '[SSL: SSLV3_ALERT_BAD_RECORD_MAC] sslv3 alert bad record mac (_ssl.c:2635)')))

During handling of the above exception, another exception occurred:

Traceback (most recent call last):
  File "/home/airflow/.local/lib/python3.8/site-packages/airflow/operators/python.py", line 192, in execute
    return_value = self.execute_callable()
  File "/home/airflow/.local/lib/python3.8/site-packages/airflow/operators/python.py", line 209, in execute_callable
    return self.python_callable(*self.op_args, **self.op_kwargs)
  File "/opt/airflow/dags/etl_scripts/pipeline.py", line 126, in extract_data
    upload_df_to_gcs(data, gcs_bucket, "outcomes.parquet",credentials=creds)
  File "/opt/airflow/dags/etl_scripts/pipeline.py", line 38, in upload_df_to_gcs
    blob.upload_from_file(parquet_buffer, content_type='application/octet-stream')
  File "/home/airflow/.local/lib/python3.8/site-packages/google/cloud/storage/blob.py", line 2763, in upload_from_file
    self._prep_and_do_upload(
  File "/home/airflow/.local/lib/python3.8/site-packages/google/cloud/storage/blob.py", line 2604, in _prep_and_do_upload
    created_json = self._do_upload(
  File "/home/airflow/.local/lib/python3.8/site-packages/google/cloud/storage/blob.py", line 2427, in _do_upload
    response = self._do_resumable_upload(
  File "/home/airflow/.local/lib/python3.8/site-packages/google/cloud/storage/blob.py", line 2263, in _do_resumable_upload
    response = upload.transmit_next_chunk(transport, timeout=timeout)
  File "/home/airflow/.local/lib/python3.8/site-packages/google/resumable_media/requests/upload.py", line 515, in transmit_next_chunk
    return _request_helpers.wait_and_retry(
  File "/home/airflow/.local/lib/python3.8/site-packages/google/resumable_media/requests/_request_helpers.py", line 178, in wait_and_retry
    raise error
  File "/home/airflow/.local/lib/python3.8/site-packages/google/resumable_media/requests/_request_helpers.py", line 155, in wait_and_retry
    response = func()
  File "/home/airflow/.local/lib/python3.8/site-packages/google/resumable_media/requests/upload.py", line 507, in retriable_request
    result = transport.request(
  File "/home/airflow/.local/lib/python3.8/site-packages/google/auth/transport/requests.py", line 542, in request
    response = super(AuthorizedSession, self).request(
  File "/home/airflow/.local/lib/python3.8/site-packages/requests/sessions.py", line 589, in request
    resp = self.send(prep, **send_kwargs)
  File "/home/airflow/.local/lib/python3.8/site-packages/requests/sessions.py", line 703, in send
    r = adapter.send(request, **kwargs)
  File "/home/airflow/.local/lib/python3.8/site-packages/requests/adapters.py", line 517, in send
    raise SSLError(e, request=request)
requests.exceptions.SSLError: HTTPSConnectionPool(host='storage.googleapis.com', port=443): Max retries exceeded with url: /upload/storage/v1/b/raw_shelter_data_csv/o?uploadType=resumable&upload_id=ABPtcPob2Dqf1tbJG1LY2lz4swQQLRYMVOW2XTsKZE5brnU6zgidat6AYDKo8MNt3kJfqAy2H76CjhdOSeLboBAGJJk_uGq_klFY6eu7HUEaR3vm (Caused by SSLError(SSLError(1, '[SSL: SSLV3_ALERT_BAD_RECORD_MAC] sslv3 alert bad record mac (_ssl.c:2635)')))
[2023-11-26T23:21:12.300+0000] {taskinstance.py:1400} INFO - Marking task as FAILED. dag_id=outcomes_dag, task_id=extract, execution_date=20231126T232100, start_date=20231126T232102, end_date=20231126T232112
[2023-11-26T23:21:12.313+0000] {standard_task_runner.py:104} ERROR - Failed to execute job 35 for task extract (HTTPSConnectionPool(host='storage.googleapis.com', port=443): Max retries exceeded with url: /upload/storage/v1/b/raw_shelter_data_csv/o?uploadType=resumable&upload_id=ABPtcPob2Dqf1tbJG1LY2lz4swQQLRYMVOW2XTsKZE5brnU6zgidat6AYDKo8MNt3kJfqAy2H76CjhdOSeLboBAGJJk_uGq_klFY6eu7HUEaR3vm (Caused by SSLError(SSLError(1, '[SSL: SSLV3_ALERT_BAD_RECORD_MAC] sslv3 alert bad record mac (_ssl.c:2635)'))); 403)
[2023-11-26T23:21:12.336+0000] {local_task_job_runner.py:228} INFO - Task exited with return code 1
[2023-11-26T23:21:12.402+0000] {taskinstance.py:2778} INFO - 0 downstream tasks scheduled from follow-on schedule check
