[2023-11-25T18:53:06.716+0000] {logging_mixin.py:154} INFO - Changing /opt/***/logs/dag_id=outcomes_dag/run_id=scheduled__2023-11-19T00:00:00+00:00/task_id=extract permission to 509
[2023-11-25T18:53:06.763+0000] {logging_mixin.py:154} INFO - Changing /opt/***/logs/dag_id=outcomes_dag/run_id=scheduled__2023-11-19T00:00:00+00:00/task_id=extract permission to 509
[2023-11-25T18:53:06.837+0000] {taskinstance.py:1159} INFO - Dependencies all met for dep_context=non-requeueable deps ti=<TaskInstance: outcomes_dag.extract scheduled__2023-11-19T00:00:00+00:00 [queued]>
[2023-11-25T18:53:06.856+0000] {taskinstance.py:1159} INFO - Dependencies all met for dep_context=requeueable deps ti=<TaskInstance: outcomes_dag.extract scheduled__2023-11-19T00:00:00+00:00 [queued]>
[2023-11-25T18:53:06.857+0000] {taskinstance.py:1361} INFO - Starting attempt 1 of 1
[2023-11-25T18:53:06.882+0000] {taskinstance.py:1382} INFO - Executing <Task(BashOperator): extract> on 2023-11-19 00:00:00+00:00
[2023-11-25T18:53:06.893+0000] {standard_task_runner.py:57} INFO - Started process 331 to run task
[2023-11-25T18:53:06.898+0000] {standard_task_runner.py:84} INFO - Running: ['***', 'tasks', 'run', 'outcomes_dag', 'extract', 'scheduled__2023-11-19T00:00:00+00:00', '--job-id', '38', '--raw', '--subdir', 'DAGS_FOLDER/outcomes_dag.py', '--cfg-path', '/tmp/tmp6oaavsj3']
[2023-11-25T18:53:06.904+0000] {standard_task_runner.py:85} INFO - Job 38: Subtask extract
[2023-11-25T18:53:06.996+0000] {logging_mixin.py:154} INFO - Changing /opt/***/logs/dag_id=outcomes_dag/run_id=scheduled__2023-11-19T00:00:00+00:00/task_id=extract permission to 509
[2023-11-25T18:53:07.000+0000] {task_command.py:416} INFO - Running <TaskInstance: outcomes_dag.extract scheduled__2023-11-19T00:00:00+00:00 [running]> on host 533b0beedf51
[2023-11-25T18:53:08.045+0000] {taskinstance.py:1662} INFO - Exporting env vars: AIRFLOW_CTX_DAG_OWNER='***' AIRFLOW_CTX_DAG_ID='outcomes_dag' AIRFLOW_CTX_TASK_ID='extract' AIRFLOW_CTX_EXECUTION_DATE='2023-11-19T00:00:00+00:00' AIRFLOW_CTX_TRY_NUMBER='1' AIRFLOW_CTX_DAG_RUN_ID='scheduled__2023-11-19T00:00:00+00:00'
[2023-11-25T18:53:08.048+0000] {subprocess.py:63} INFO - Tmp dir root location: /tmp
[2023-11-25T18:53:08.050+0000] {subprocess.py:75} INFO - Running command: ['/bin/bash', '-c', 'curl --create-dirs -o /opt/***/data/2023-11-19/downloads/outcomes_2023-11-19.csv https://data.austintexas.gov/api/views/9t4d-g238/rows.csv']
[2023-11-25T18:53:08.072+0000] {subprocess.py:86} INFO - Output:
[2023-11-25T18:53:08.085+0000] {subprocess.py:93} INFO -   % Total    % Received % Xferd  Average Speed   Time    Time     Time  Current
[2023-11-25T18:53:08.086+0000] {subprocess.py:93} INFO -                                  Dload  Upload   Total   Spent    Left  Speed
[2023-11-25T18:53:14.224+0000] {subprocess.py:93} INFO -   0     0    0     0    0     0      0      0 --:--:-- --:--:-- --:--:--     0100 1279k    0 1279k    0     0  1295k      0 --:--:-- --:--:-- --:--:-- 1294k100 5422k    0 5422k    0     0  2713k      0 --:--:--  0:00:01 --:--:-- 2712k100 8797k    0 8797k    0     0  2938k      0 --:--:--  0:00:02 --:--:-- 2937k100 11.8M    0 11.8M    0     0  3042k      0 --:--:--  0:00:04 --:--:-- 3042k100 15.2M    0 15.2M    0     0  3122k      0 --:--:--  0:00:04 --:--:-- 3121k100 18.4M    0 18.4M    0     0  3153k      0 --:--:--  0:00:05 --:--:-- 3520k100 19.0M    0 19.0M    0     0  3174k      0 --:--:--  0:00:06 --:--:-- 3396k
[2023-11-25T18:53:14.228+0000] {subprocess.py:97} INFO - Command exited with return code 0
[2023-11-25T18:53:14.258+0000] {taskinstance.py:1400} INFO - Marking task as SUCCESS. dag_id=outcomes_dag, task_id=extract, execution_date=20231119T000000, start_date=20231125T185306, end_date=20231125T185314
[2023-11-25T18:53:14.337+0000] {local_task_job_runner.py:228} INFO - Task exited with return code 0
[2023-11-25T18:53:14.362+0000] {taskinstance.py:2778} INFO - 1 downstream tasks scheduled from follow-on schedule check
[2023-11-26T19:47:56.861+0000] {logging_mixin.py:154} INFO - Changing /opt/***/logs/dag_id=outcomes_dag/run_id=scheduled__2023-11-19T00:00:00+00:00/task_id=extract permission to 509
[2023-11-26T19:47:56.911+0000] {logging_mixin.py:154} INFO - Changing /opt/***/logs/dag_id=outcomes_dag/run_id=scheduled__2023-11-19T00:00:00+00:00/task_id=extract permission to 509
[2023-11-26T19:47:56.983+0000] {taskinstance.py:1159} INFO - Dependencies all met for dep_context=non-requeueable deps ti=<TaskInstance: outcomes_dag.extract scheduled__2023-11-19T00:00:00+00:00 [queued]>
[2023-11-26T19:47:57.007+0000] {taskinstance.py:1159} INFO - Dependencies all met for dep_context=requeueable deps ti=<TaskInstance: outcomes_dag.extract scheduled__2023-11-19T00:00:00+00:00 [queued]>
[2023-11-26T19:47:57.007+0000] {taskinstance.py:1361} INFO - Starting attempt 1 of 1
[2023-11-26T19:47:57.027+0000] {taskinstance.py:1382} INFO - Executing <Task(BashOperator): extract> on 2023-11-19 00:00:00+00:00
[2023-11-26T19:47:57.035+0000] {standard_task_runner.py:57} INFO - Started process 669 to run task
[2023-11-26T19:47:57.040+0000] {standard_task_runner.py:84} INFO - Running: ['***', 'tasks', 'run', 'outcomes_dag', 'extract', 'scheduled__2023-11-19T00:00:00+00:00', '--job-id', '71', '--raw', '--subdir', 'DAGS_FOLDER/outcomes_dag.py', '--cfg-path', '/tmp/tmpnc_6n59i']
[2023-11-26T19:47:57.045+0000] {standard_task_runner.py:85} INFO - Job 71: Subtask extract
[2023-11-26T19:47:57.131+0000] {logging_mixin.py:154} INFO - Changing /opt/***/logs/dag_id=outcomes_dag/run_id=scheduled__2023-11-19T00:00:00+00:00/task_id=extract permission to 509
[2023-11-26T19:47:57.135+0000] {task_command.py:416} INFO - Running <TaskInstance: outcomes_dag.extract scheduled__2023-11-19T00:00:00+00:00 [running]> on host a66846cad9d1
[2023-11-26T19:48:00.499+0000] {taskinstance.py:1662} INFO - Exporting env vars: AIRFLOW_CTX_DAG_OWNER='***' AIRFLOW_CTX_DAG_ID='outcomes_dag' AIRFLOW_CTX_TASK_ID='extract' AIRFLOW_CTX_EXECUTION_DATE='2023-11-19T00:00:00+00:00' AIRFLOW_CTX_TRY_NUMBER='1' AIRFLOW_CTX_DAG_RUN_ID='scheduled__2023-11-19T00:00:00+00:00'
[2023-11-26T19:48:00.502+0000] {subprocess.py:63} INFO - Tmp dir root location: /tmp
[2023-11-26T19:48:00.504+0000] {subprocess.py:75} INFO - Running command: ['/bin/bash', '-c', 'curl --create-dirs -o /opt/***/data/2023-11-19/downloads/outcomes_2023-11-19.csv https://data.austintexas.gov/api/views/9t4d-g238/rows.csv']
[2023-11-26T19:48:00.537+0000] {subprocess.py:86} INFO - Output:
[2023-11-26T19:48:00.559+0000] {subprocess.py:93} INFO -   % Total    % Received % Xferd  Average Speed   Time    Time     Time  Current
[2023-11-26T19:48:00.560+0000] {subprocess.py:93} INFO -                                  Dload  Upload   Total   Spent    Left  Speed
[2023-11-26T19:48:44.630+0000] {subprocess.py:93} INFO -   0     0    0     0    0     0      0      0 --:--:-- --:--:-- --:--:--     0  0     0    0     0    0     0      0      0 --:--:--  0:00:01 --:--:--     0  0     0    0     0    0     0      0      0 --:--:--  0:00:02 --:--:--     0100  367k    0  367k    0     0   103k      0 --:--:--  0:00:03 --:--:--  103k100 1279k    0 1279k    0     0   276k      0 --:--:--  0:00:04 --:--:--  276k100 1630k    0 1630k    0     0   280k      0 --:--:--  0:00:05 --:--:--  280k100 1918k    0 1918k    0     0   293k      0 --:--:--  0:00:06 --:--:--  376k100 2286k    0 2286k    0     0   302k      0 --:--:--  0:00:07 --:--:--  458k100 2830k    0 2830k    0     0   320k      0 --:--:--  0:00:08 --:--:--  467k100 3486k    0 3486k    0     0   359k      0 --:--:--  0:00:09 --:--:--  434k100 3870k    0 3870k    0     0   364k      0 --:--:--  0:00:10 --:--:--  466k100 4270k    0 4270k    0     0   368k      0 --:--:--  0:00:11 --:--:--  466k100 4622k    0 4622k    0     0   355k      0 --:--:--  0:00:12 --:--:--  430k100 4910k    0 4910k    0     0   360k      0 --:--:--  0:00:13 --:--:--  434k100 5166k    0 5166k    0     0   345k      0 --:--:--  0:00:14 --:--:--  320k100 5166k    0 5166k    0     0   327k      0 --:--:--  0:00:15 --:--:--  250k100 5166k    0 5166k    0     0   306k      0 --:--:--  0:00:16 --:--:--  170k100 5182k    0 5182k    0     0   289k      0 --:--:--  0:00:17 --:--:--  113k100 7246k    0 7246k    0     0   387k      0 --:--:--  0:00:18 --:--:--  457k100 7646k    0 7646k    0     0   391k      0 --:--:--  0:00:19 --:--:--  539k100 8398k    0 8398k    0     0   406k      0 --:--:--  0:00:20 --:--:--  659k100 8941k    0 8941k    0     0   414k      0 --:--:--  0:00:21 --:--:--  799k100 9437k    0 9437k    0     0   416k      0 --:--:--  0:00:22 --:--:--  893k100 9693k    0 9693k    0     0   411k      0 --:--:--  0:00:23 --:--:--  504k100  9.8M    0  9.8M    0     0   407k      0 --:--:--  0:00:24 --:--:--  467k100 10.2M    0 10.2M    0     0   407k      0 --:--:--  0:00:25 --:--:--  411k100 10.4M    0 10.4M    0     0   402k      0 --:--:--  0:00:26 --:--:--  349k100 11.0M    0 11.0M    0     0   407k      0 --:--:--  0:00:27 --:--:--  370k100 11.5M    0 11.5M    0     0   412k      0 --:--:--  0:00:28 --:--:--  418k100 11.6M    0 11.6M    0     0   402k      0 --:--:--  0:00:29 --:--:--  378k100 11.6M    0 11.6M    0     0   375k      0 --:--:--  0:00:31 --:--:--  239k100 13.1M    0 13.1M    0     0   411k      0 --:--:--  0:00:32 --:--:--  452k100 13.5M    0 13.5M    0     0   412k      0 --:--:--  0:00:33 --:--:--  433k100 14.3M    0 14.3M    0     0   424k      0 --:--:--  0:00:34 --:--:--  478k100 14.8M    0 14.8M    0     0   425k      0 --:--:--  0:00:35 --:--:--  539k100 15.2M    0 15.2M    0     0   421k      0 --:--:--  0:00:36 --:--:--  708k100 15.2M    0 15.2M    0     0   407k      0 --:--:--  0:00:38 --:--:--  382k100 15.2M    0 15.2M    0     0   396k      0 --:--:--  0:00:39 --:--:--  300k100 15.2M    0 15.2M    0     0   385k      0 --:--:--  0:00:40 --:--:--  155k100 15.2M    0 15.2M    0     0   382k      0 --:--:--  0:00:40 --:--:-- 80256100 17.7M    0 17.7M    0     0   433k      0 --:--:--  0:00:41 --:--:--  528k100 18.1M    0 18.1M    0     0   436k      0 --:--:--  0:00:42 --:--:--  686k100 18.6M    0 18.6M    0     0   436k      0 --:--:--  0:00:43 --:--:--  799k100 19.0M    0 19.0M    0     0   442k      0 --:--:--  0:00:44 --:--:-- 1054k
[2023-11-26T19:48:44.702+0000] {subprocess.py:97} INFO - Command exited with return code 0
[2023-11-26T19:48:47.755+0000] {job.py:219} ERROR - Job heartbeat got an exception
Traceback (most recent call last):
  File "/home/airflow/.local/lib/python3.8/site-packages/sqlalchemy/engine/base.py", line 3371, in _wrap_pool_connect
    return fn()
  File "/home/airflow/.local/lib/python3.8/site-packages/sqlalchemy/pool/base.py", line 327, in connect
    return _ConnectionFairy._checkout(self)
  File "/home/airflow/.local/lib/python3.8/site-packages/sqlalchemy/pool/base.py", line 894, in _checkout
    fairy = _ConnectionRecord.checkout(pool)
  File "/home/airflow/.local/lib/python3.8/site-packages/sqlalchemy/pool/base.py", line 493, in checkout
    rec = pool._do_get()
  File "/home/airflow/.local/lib/python3.8/site-packages/sqlalchemy/pool/impl.py", line 256, in _do_get
    return self._create_connection()
  File "/home/airflow/.local/lib/python3.8/site-packages/sqlalchemy/pool/base.py", line 273, in _create_connection
    return _ConnectionRecord(self)
  File "/home/airflow/.local/lib/python3.8/site-packages/sqlalchemy/pool/base.py", line 388, in __init__
    self.__connect()
  File "/home/airflow/.local/lib/python3.8/site-packages/sqlalchemy/pool/base.py", line 691, in __connect
    pool.logger.debug("Error on connect(): %s", e)
  File "/home/airflow/.local/lib/python3.8/site-packages/sqlalchemy/util/langhelpers.py", line 70, in __exit__
    compat.raise_(
  File "/home/airflow/.local/lib/python3.8/site-packages/sqlalchemy/util/compat.py", line 211, in raise_
    raise exception
  File "/home/airflow/.local/lib/python3.8/site-packages/sqlalchemy/pool/base.py", line 686, in __connect
    self.dbapi_connection = connection = pool._invoke_creator(self)
  File "/home/airflow/.local/lib/python3.8/site-packages/sqlalchemy/engine/create.py", line 574, in connect
    return dialect.connect(*cargs, **cparams)
  File "/home/airflow/.local/lib/python3.8/site-packages/sqlalchemy/engine/default.py", line 598, in connect
    return self.dbapi.connect(*cargs, **cparams)
  File "/home/airflow/.local/lib/python3.8/site-packages/psycopg2/__init__.py", line 122, in connect
    conn = _connect(dsn, connection_factory=connection_factory, **kwasync)
psycopg2.OperationalError: could not translate host name "postgres" to address: Temporary failure in name resolution


The above exception was the direct cause of the following exception:

Traceback (most recent call last):
  File "/home/airflow/.local/lib/python3.8/site-packages/airflow/jobs/job.py", line 190, in heartbeat
    session.merge(self)
  File "/home/airflow/.local/lib/python3.8/site-packages/sqlalchemy/orm/session.py", line 3056, in merge
    return self._merge(
  File "/home/airflow/.local/lib/python3.8/site-packages/sqlalchemy/orm/session.py", line 3136, in _merge
    merged = self.get(
  File "/home/airflow/.local/lib/python3.8/site-packages/sqlalchemy/orm/session.py", line 2853, in get
    return self._get_impl(
  File "/home/airflow/.local/lib/python3.8/site-packages/sqlalchemy/orm/session.py", line 2975, in _get_impl
    return db_load_fn(
  File "/home/airflow/.local/lib/python3.8/site-packages/sqlalchemy/orm/loading.py", line 530, in load_on_pk_identity
    session.execute(
  File "/home/airflow/.local/lib/python3.8/site-packages/sqlalchemy/orm/session.py", line 1716, in execute
    conn = self._connection_for_bind(bind)
  File "/home/airflow/.local/lib/python3.8/site-packages/sqlalchemy/orm/session.py", line 1555, in _connection_for_bind
    return self._transaction._connection_for_bind(
  File "/home/airflow/.local/lib/python3.8/site-packages/sqlalchemy/orm/session.py", line 750, in _connection_for_bind
    conn = bind.connect()
  File "/home/airflow/.local/lib/python3.8/site-packages/sqlalchemy/future/engine.py", line 406, in connect
    return super(Engine, self).connect()
  File "/home/airflow/.local/lib/python3.8/site-packages/sqlalchemy/engine/base.py", line 3325, in connect
    return self._connection_cls(self, close_with_result=close_with_result)
  File "/home/airflow/.local/lib/python3.8/site-packages/sqlalchemy/engine/base.py", line 96, in __init__
    else engine.raw_connection()
  File "/home/airflow/.local/lib/python3.8/site-packages/sqlalchemy/engine/base.py", line 3404, in raw_connection
    return self._wrap_pool_connect(self.pool.connect, _connection)
  File "/home/airflow/.local/lib/python3.8/site-packages/sqlalchemy/engine/base.py", line 3374, in _wrap_pool_connect
    Connection._handle_dbapi_exception_noconnection(
  File "/home/airflow/.local/lib/python3.8/site-packages/sqlalchemy/engine/base.py", line 2208, in _handle_dbapi_exception_noconnection
    util.raise_(
  File "/home/airflow/.local/lib/python3.8/site-packages/sqlalchemy/util/compat.py", line 211, in raise_
    raise exception
  File "/home/airflow/.local/lib/python3.8/site-packages/sqlalchemy/engine/base.py", line 3371, in _wrap_pool_connect
    return fn()
  File "/home/airflow/.local/lib/python3.8/site-packages/sqlalchemy/pool/base.py", line 327, in connect
    return _ConnectionFairy._checkout(self)
  File "/home/airflow/.local/lib/python3.8/site-packages/sqlalchemy/pool/base.py", line 894, in _checkout
    fairy = _ConnectionRecord.checkout(pool)
  File "/home/airflow/.local/lib/python3.8/site-packages/sqlalchemy/pool/base.py", line 493, in checkout
    rec = pool._do_get()
  File "/home/airflow/.local/lib/python3.8/site-packages/sqlalchemy/pool/impl.py", line 256, in _do_get
    return self._create_connection()
  File "/home/airflow/.local/lib/python3.8/site-packages/sqlalchemy/pool/base.py", line 273, in _create_connection
    return _ConnectionRecord(self)
  File "/home/airflow/.local/lib/python3.8/site-packages/sqlalchemy/pool/base.py", line 388, in __init__
    self.__connect()
  File "/home/airflow/.local/lib/python3.8/site-packages/sqlalchemy/pool/base.py", line 691, in __connect
    pool.logger.debug("Error on connect(): %s", e)
  File "/home/airflow/.local/lib/python3.8/site-packages/sqlalchemy/util/langhelpers.py", line 70, in __exit__
    compat.raise_(
  File "/home/airflow/.local/lib/python3.8/site-packages/sqlalchemy/util/compat.py", line 211, in raise_
    raise exception
  File "/home/airflow/.local/lib/python3.8/site-packages/sqlalchemy/pool/base.py", line 686, in __connect
    self.dbapi_connection = connection = pool._invoke_creator(self)
  File "/home/airflow/.local/lib/python3.8/site-packages/sqlalchemy/engine/create.py", line 574, in connect
    return dialect.connect(*cargs, **cparams)
  File "/home/airflow/.local/lib/python3.8/site-packages/sqlalchemy/engine/default.py", line 598, in connect
    return self.dbapi.connect(*cargs, **cparams)
  File "/home/airflow/.local/lib/python3.8/site-packages/psycopg2/__init__.py", line 122, in connect
    conn = _connect(dsn, connection_factory=connection_factory, **kwasync)
sqlalchemy.exc.OperationalError: (psycopg2.OperationalError) could not translate host name "postgres" to address: Temporary failure in name resolution

(Background on this error at: https://sqlalche.me/e/14/e3q8)
[2023-11-26T19:48:55.329+0000] {taskinstance.py:1937} ERROR - Task failed with exception
Traceback (most recent call last):
  File "/home/airflow/.local/lib/python3.8/site-packages/sqlalchemy/engine/base.py", line 3371, in _wrap_pool_connect
    return fn()
  File "/home/airflow/.local/lib/python3.8/site-packages/sqlalchemy/pool/base.py", line 327, in connect
    return _ConnectionFairy._checkout(self)
  File "/home/airflow/.local/lib/python3.8/site-packages/sqlalchemy/pool/base.py", line 894, in _checkout
    fairy = _ConnectionRecord.checkout(pool)
  File "/home/airflow/.local/lib/python3.8/site-packages/sqlalchemy/pool/base.py", line 493, in checkout
    rec = pool._do_get()
  File "/home/airflow/.local/lib/python3.8/site-packages/sqlalchemy/pool/impl.py", line 256, in _do_get
    return self._create_connection()
  File "/home/airflow/.local/lib/python3.8/site-packages/sqlalchemy/pool/base.py", line 273, in _create_connection
    return _ConnectionRecord(self)
  File "/home/airflow/.local/lib/python3.8/site-packages/sqlalchemy/pool/base.py", line 388, in __init__
    self.__connect()
  File "/home/airflow/.local/lib/python3.8/site-packages/sqlalchemy/pool/base.py", line 691, in __connect
    pool.logger.debug("Error on connect(): %s", e)
  File "/home/airflow/.local/lib/python3.8/site-packages/sqlalchemy/util/langhelpers.py", line 70, in __exit__
    compat.raise_(
  File "/home/airflow/.local/lib/python3.8/site-packages/sqlalchemy/util/compat.py", line 211, in raise_
    raise exception
  File "/home/airflow/.local/lib/python3.8/site-packages/sqlalchemy/pool/base.py", line 686, in __connect
    self.dbapi_connection = connection = pool._invoke_creator(self)
  File "/home/airflow/.local/lib/python3.8/site-packages/sqlalchemy/engine/create.py", line 574, in connect
    return dialect.connect(*cargs, **cparams)
  File "/home/airflow/.local/lib/python3.8/site-packages/sqlalchemy/engine/default.py", line 598, in connect
    return self.dbapi.connect(*cargs, **cparams)
  File "/home/airflow/.local/lib/python3.8/site-packages/psycopg2/__init__.py", line 122, in connect
    conn = _connect(dsn, connection_factory=connection_factory, **kwasync)
psycopg2.OperationalError: could not translate host name "postgres" to address: Temporary failure in name resolution


The above exception was the direct cause of the following exception:

Traceback (most recent call last):
  File "/home/airflow/.local/lib/python3.8/site-packages/airflow/utils/session.py", line 76, in wrapper
    return func(*args, **kwargs)
  File "/home/airflow/.local/lib/python3.8/site-packages/airflow/models/taskinstance.py", line 2479, in xcom_push
    XCom.set(
  File "/home/airflow/.local/lib/python3.8/site-packages/airflow/utils/session.py", line 76, in wrapper
    return func(*args, **kwargs)
  File "/home/airflow/.local/lib/python3.8/site-packages/airflow/models/xcom.py", line 219, in set
    dag_run_id = session.query(DagRun.id).filter_by(dag_id=dag_id, run_id=run_id).scalar()
  File "/home/airflow/.local/lib/python3.8/site-packages/sqlalchemy/orm/query.py", line 2893, in scalar
    ret = self.one()
  File "/home/airflow/.local/lib/python3.8/site-packages/sqlalchemy/orm/query.py", line 2870, in one
    return self._iter().one()
  File "/home/airflow/.local/lib/python3.8/site-packages/sqlalchemy/orm/query.py", line 2916, in _iter
    result = self.session.execute(
  File "/home/airflow/.local/lib/python3.8/site-packages/sqlalchemy/orm/session.py", line 1716, in execute
    conn = self._connection_for_bind(bind)
  File "/home/airflow/.local/lib/python3.8/site-packages/sqlalchemy/orm/session.py", line 1555, in _connection_for_bind
    return self._transaction._connection_for_bind(
  File "/home/airflow/.local/lib/python3.8/site-packages/sqlalchemy/orm/session.py", line 750, in _connection_for_bind
    conn = bind.connect()
  File "/home/airflow/.local/lib/python3.8/site-packages/sqlalchemy/future/engine.py", line 406, in connect
    return super(Engine, self).connect()
  File "/home/airflow/.local/lib/python3.8/site-packages/sqlalchemy/engine/base.py", line 3325, in connect
    return self._connection_cls(self, close_with_result=close_with_result)
  File "/home/airflow/.local/lib/python3.8/site-packages/sqlalchemy/engine/base.py", line 96, in __init__
    else engine.raw_connection()
  File "/home/airflow/.local/lib/python3.8/site-packages/sqlalchemy/engine/base.py", line 3404, in raw_connection
    return self._wrap_pool_connect(self.pool.connect, _connection)
  File "/home/airflow/.local/lib/python3.8/site-packages/sqlalchemy/engine/base.py", line 3374, in _wrap_pool_connect
    Connection._handle_dbapi_exception_noconnection(
  File "/home/airflow/.local/lib/python3.8/site-packages/sqlalchemy/engine/base.py", line 2208, in _handle_dbapi_exception_noconnection
    util.raise_(
  File "/home/airflow/.local/lib/python3.8/site-packages/sqlalchemy/util/compat.py", line 211, in raise_
    raise exception
  File "/home/airflow/.local/lib/python3.8/site-packages/sqlalchemy/engine/base.py", line 3371, in _wrap_pool_connect
    return fn()
  File "/home/airflow/.local/lib/python3.8/site-packages/sqlalchemy/pool/base.py", line 327, in connect
    return _ConnectionFairy._checkout(self)
  File "/home/airflow/.local/lib/python3.8/site-packages/sqlalchemy/pool/base.py", line 894, in _checkout
    fairy = _ConnectionRecord.checkout(pool)
  File "/home/airflow/.local/lib/python3.8/site-packages/sqlalchemy/pool/base.py", line 493, in checkout
    rec = pool._do_get()
  File "/home/airflow/.local/lib/python3.8/site-packages/sqlalchemy/pool/impl.py", line 256, in _do_get
    return self._create_connection()
  File "/home/airflow/.local/lib/python3.8/site-packages/sqlalchemy/pool/base.py", line 273, in _create_connection
    return _ConnectionRecord(self)
  File "/home/airflow/.local/lib/python3.8/site-packages/sqlalchemy/pool/base.py", line 388, in __init__
    self.__connect()
  File "/home/airflow/.local/lib/python3.8/site-packages/sqlalchemy/pool/base.py", line 691, in __connect
    pool.logger.debug("Error on connect(): %s", e)
  File "/home/airflow/.local/lib/python3.8/site-packages/sqlalchemy/util/langhelpers.py", line 70, in __exit__
    compat.raise_(
  File "/home/airflow/.local/lib/python3.8/site-packages/sqlalchemy/util/compat.py", line 211, in raise_
    raise exception
  File "/home/airflow/.local/lib/python3.8/site-packages/sqlalchemy/pool/base.py", line 686, in __connect
    self.dbapi_connection = connection = pool._invoke_creator(self)
  File "/home/airflow/.local/lib/python3.8/site-packages/sqlalchemy/engine/create.py", line 574, in connect
    return dialect.connect(*cargs, **cparams)
  File "/home/airflow/.local/lib/python3.8/site-packages/sqlalchemy/engine/default.py", line 598, in connect
    return self.dbapi.connect(*cargs, **cparams)
  File "/home/airflow/.local/lib/python3.8/site-packages/psycopg2/__init__.py", line 122, in connect
    conn = _connect(dsn, connection_factory=connection_factory, **kwasync)
sqlalchemy.exc.OperationalError: (psycopg2.OperationalError) could not translate host name "postgres" to address: Temporary failure in name resolution

(Background on this error at: https://sqlalche.me/e/14/e3q8)
[2023-11-26T19:48:56.010+0000] {taskinstance.py:1400} INFO - Marking task as FAILED. dag_id=outcomes_dag, task_id=extract, execution_date=20231119T000000, start_date=20231126T194756, end_date=20231126T194856
[2023-11-26T19:48:56.063+0000] {standard_task_runner.py:104} ERROR - Failed to execute job 71 for task extract ((psycopg2.OperationalError) could not translate host name "postgres" to address: Temporary failure in name resolution

(Background on this error at: https://sqlalche.me/e/14/e3q8); 669)
[2023-11-26T19:48:56.118+0000] {local_task_job_runner.py:228} INFO - Task exited with return code 1
[2023-11-26T19:48:56.181+0000] {taskinstance.py:2778} INFO - 0 downstream tasks scheduled from follow-on schedule check
[2023-11-26T23:09:01.723+0000] {logging_mixin.py:154} INFO - Changing /opt/***/logs/dag_id=outcomes_dag/run_id=scheduled__2023-11-19T00:00:00+00:00/task_id=extract permission to 509
[2023-11-26T23:09:01.789+0000] {logging_mixin.py:154} INFO - Changing /opt/***/logs/dag_id=outcomes_dag/run_id=scheduled__2023-11-19T00:00:00+00:00/task_id=extract permission to 509
[2023-11-26T23:09:01.880+0000] {taskinstance.py:1159} INFO - Dependencies all met for dep_context=non-requeueable deps ti=<TaskInstance: outcomes_dag.extract scheduled__2023-11-19T00:00:00+00:00 [queued]>
[2023-11-26T23:09:01.912+0000] {taskinstance.py:1159} INFO - Dependencies all met for dep_context=requeueable deps ti=<TaskInstance: outcomes_dag.extract scheduled__2023-11-19T00:00:00+00:00 [queued]>
[2023-11-26T23:09:01.913+0000] {taskinstance.py:1361} INFO - Starting attempt 1 of 1
[2023-11-26T23:09:02.860+0000] {taskinstance.py:1382} INFO - Executing <Task(PythonOperator): extract> on 2023-11-19 00:00:00+00:00
[2023-11-26T23:09:02.873+0000] {standard_task_runner.py:57} INFO - Started process 167 to run task
[2023-11-26T23:09:02.876+0000] {standard_task_runner.py:84} INFO - Running: ['***', 'tasks', 'run', 'outcomes_dag', 'extract', 'scheduled__2023-11-19T00:00:00+00:00', '--job-id', '24', '--raw', '--subdir', 'DAGS_FOLDER/outcomes_dag.py', '--cfg-path', '/tmp/tmp43cj_t_m']
[2023-11-26T23:09:02.880+0000] {standard_task_runner.py:85} INFO - Job 24: Subtask extract
[2023-11-26T23:09:02.961+0000] {logging_mixin.py:154} INFO - Changing /opt/***/logs/dag_id=outcomes_dag/run_id=scheduled__2023-11-19T00:00:00+00:00/task_id=extract permission to 509
[2023-11-26T23:09:02.965+0000] {task_command.py:416} INFO - Running <TaskInstance: outcomes_dag.extract scheduled__2023-11-19T00:00:00+00:00 [running]> on host 613ffde293d8
[2023-11-26T23:09:03.081+0000] {taskinstance.py:1662} INFO - Exporting env vars: AIRFLOW_CTX_DAG_OWNER='***' AIRFLOW_CTX_DAG_ID='outcomes_dag' AIRFLOW_CTX_TASK_ID='extract' AIRFLOW_CTX_EXECUTION_DATE='2023-11-19T00:00:00+00:00' AIRFLOW_CTX_TRY_NUMBER='1' AIRFLOW_CTX_DAG_RUN_ID='scheduled__2023-11-19T00:00:00+00:00'
[2023-11-26T23:09:03.084+0000] {taskinstance.py:1937} ERROR - Task failed with exception
Traceback (most recent call last):
  File "/home/airflow/.local/lib/python3.8/site-packages/airflow/operators/python.py", line 192, in execute
    return_value = self.execute_callable()
  File "/home/airflow/.local/lib/python3.8/site-packages/airflow/operators/python.py", line 209, in execute_callable
    return self.python_callable(*self.op_args, **self.op_kwargs)
TypeError: extract_data() missing 3 required positional arguments: 'source_url', 'gcs_bucket', and 'creds'
[2023-11-26T23:09:03.098+0000] {taskinstance.py:1400} INFO - Marking task as FAILED. dag_id=outcomes_dag, task_id=extract, execution_date=20231119T000000, start_date=20231126T230901, end_date=20231126T230903
[2023-11-26T23:09:03.120+0000] {standard_task_runner.py:104} ERROR - Failed to execute job 24 for task extract (extract_data() missing 3 required positional arguments: 'source_url', 'gcs_bucket', and 'creds'; 167)
[2023-11-26T23:09:03.170+0000] {local_task_job_runner.py:228} INFO - Task exited with return code 1
[2023-11-26T23:09:03.281+0000] {taskinstance.py:2778} INFO - 0 downstream tasks scheduled from follow-on schedule check
