[2023-11-25T18:53:15.324+0000] {logging_mixin.py:154} INFO - Changing /opt/***/logs/dag_id=outcomes_dag/run_id=scheduled__2023-11-20T00:00:00+00:00/task_id=transform permission to 509
[2023-11-25T18:53:15.382+0000] {logging_mixin.py:154} INFO - Changing /opt/***/logs/dag_id=outcomes_dag/run_id=scheduled__2023-11-20T00:00:00+00:00/task_id=transform permission to 509
[2023-11-25T18:53:15.437+0000] {taskinstance.py:1159} INFO - Dependencies all met for dep_context=non-requeueable deps ti=<TaskInstance: outcomes_dag.transform scheduled__2023-11-20T00:00:00+00:00 [queued]>
[2023-11-25T18:53:15.458+0000] {taskinstance.py:1159} INFO - Dependencies all met for dep_context=requeueable deps ti=<TaskInstance: outcomes_dag.transform scheduled__2023-11-20T00:00:00+00:00 [queued]>
[2023-11-25T18:53:15.459+0000] {taskinstance.py:1361} INFO - Starting attempt 1 of 1
[2023-11-25T18:53:15.488+0000] {taskinstance.py:1382} INFO - Executing <Task(PythonOperator): transform> on 2023-11-20 00:00:00+00:00
[2023-11-25T18:53:15.500+0000] {standard_task_runner.py:57} INFO - Started process 364 to run task
[2023-11-25T18:53:15.504+0000] {standard_task_runner.py:84} INFO - Running: ['***', 'tasks', 'run', 'outcomes_dag', 'transform', 'scheduled__2023-11-20T00:00:00+00:00', '--job-id', '47', '--raw', '--subdir', 'DAGS_FOLDER/outcomes_dag.py', '--cfg-path', '/tmp/tmpw76gzzwy']
[2023-11-25T18:53:15.508+0000] {standard_task_runner.py:85} INFO - Job 47: Subtask transform
[2023-11-25T18:53:15.589+0000] {logging_mixin.py:154} INFO - Changing /opt/***/logs/dag_id=outcomes_dag/run_id=scheduled__2023-11-20T00:00:00+00:00/task_id=transform permission to 509
[2023-11-25T18:53:15.593+0000] {task_command.py:416} INFO - Running <TaskInstance: outcomes_dag.transform scheduled__2023-11-20T00:00:00+00:00 [running]> on host 533b0beedf51
[2023-11-25T18:53:16.127+0000] {taskinstance.py:1662} INFO - Exporting env vars: AIRFLOW_CTX_DAG_OWNER='***' AIRFLOW_CTX_DAG_ID='outcomes_dag' AIRFLOW_CTX_TASK_ID='transform' AIRFLOW_CTX_EXECUTION_DATE='2023-11-20T00:00:00+00:00' AIRFLOW_CTX_TRY_NUMBER='1' AIRFLOW_CTX_DAG_RUN_ID='scheduled__2023-11-20T00:00:00+00:00'
[2023-11-25T18:53:16.699+0000] {logging_mixin.py:154} INFO - In function transform_data()
[2023-11-25T18:53:47.238+0000] {python.py:194} INFO - Done. Returned value was:        Animal ID        Name  ... Date of Outcome Years Age upon Outcome
0        A794011       Chunk  ...      2019-05-08                      2
1        A776359       Gizmo  ...      2018-07-18                      1
2        A821648         NaN  ...      2020-08-16                      1
3        A720371       Moose  ...      2016-02-13                      0
4        A674754         NaN  ...      2014-03-18                      0
...          ...         ...  ...             ...                    ...
157342   A859974  *Lady Gaga  ...      2022-08-16                     10
157343   A856973      *Suede  ...      2022-06-11                      1
157344   A852036       Queen  ...      2022-03-17                      0
157345   A852775     A852775  ...      2022-05-18                      0
157346   A854626     A854626  ...      2022-05-03                      0

[157347 rows x 12 columns]
[2023-11-25T18:53:48.291+0000] {taskinstance.py:1400} INFO - Marking task as SUCCESS. dag_id=outcomes_dag, task_id=transform, execution_date=20231120T000000, start_date=20231125T185315, end_date=20231125T185348
[2023-11-25T18:53:48.362+0000] {local_task_job_runner.py:228} INFO - Task exited with return code 0
[2023-11-25T18:53:48.385+0000] {taskinstance.py:2778} INFO - 0 downstream tasks scheduled from follow-on schedule check
[2023-11-26T19:48:13.206+0000] {logging_mixin.py:154} INFO - Changing /opt/***/logs/dag_id=outcomes_dag/run_id=scheduled__2023-11-20T00:00:00+00:00/task_id=transform permission to 509
[2023-11-26T19:48:13.255+0000] {logging_mixin.py:154} INFO - Changing /opt/***/logs/dag_id=outcomes_dag/run_id=scheduled__2023-11-20T00:00:00+00:00/task_id=transform permission to 509
[2023-11-26T19:48:13.307+0000] {taskinstance.py:1159} INFO - Dependencies all met for dep_context=non-requeueable deps ti=<TaskInstance: outcomes_dag.transform scheduled__2023-11-20T00:00:00+00:00 [queued]>
[2023-11-26T19:48:13.327+0000] {taskinstance.py:1159} INFO - Dependencies all met for dep_context=requeueable deps ti=<TaskInstance: outcomes_dag.transform scheduled__2023-11-20T00:00:00+00:00 [queued]>
[2023-11-26T19:48:13.328+0000] {taskinstance.py:1361} INFO - Starting attempt 1 of 1
[2023-11-26T19:48:13.358+0000] {taskinstance.py:1382} INFO - Executing <Task(PythonOperator): transform> on 2023-11-20 00:00:00+00:00
[2023-11-26T19:48:13.369+0000] {standard_task_runner.py:57} INFO - Started process 698 to run task
[2023-11-26T19:48:13.376+0000] {standard_task_runner.py:84} INFO - Running: ['***', 'tasks', 'run', 'outcomes_dag', 'transform', 'scheduled__2023-11-20T00:00:00+00:00', '--job-id', '79', '--raw', '--subdir', 'DAGS_FOLDER/outcomes_dag.py', '--cfg-path', '/tmp/tmp8xvfw3jt']
[2023-11-26T19:48:13.381+0000] {standard_task_runner.py:85} INFO - Job 79: Subtask transform
[2023-11-26T19:48:13.473+0000] {logging_mixin.py:154} INFO - Changing /opt/***/logs/dag_id=outcomes_dag/run_id=scheduled__2023-11-20T00:00:00+00:00/task_id=transform permission to 509
[2023-11-26T19:48:13.478+0000] {task_command.py:416} INFO - Running <TaskInstance: outcomes_dag.transform scheduled__2023-11-20T00:00:00+00:00 [running]> on host a66846cad9d1
[2023-11-26T19:48:14.160+0000] {taskinstance.py:1662} INFO - Exporting env vars: AIRFLOW_CTX_DAG_OWNER='***' AIRFLOW_CTX_DAG_ID='outcomes_dag' AIRFLOW_CTX_TASK_ID='transform' AIRFLOW_CTX_EXECUTION_DATE='2023-11-20T00:00:00+00:00' AIRFLOW_CTX_TRY_NUMBER='1' AIRFLOW_CTX_DAG_RUN_ID='scheduled__2023-11-20T00:00:00+00:00'
[2023-11-26T19:48:18.814+0000] {logging_mixin.py:154} INFO - In function transform_data()
[2023-11-26T19:48:49.117+0000] {job.py:219} ERROR - Job heartbeat got an exception
Traceback (most recent call last):
  File "/home/airflow/.local/lib/python3.8/site-packages/sqlalchemy/engine/base.py", line 3371, in _wrap_pool_connect
    return fn()
  File "/home/airflow/.local/lib/python3.8/site-packages/sqlalchemy/pool/base.py", line 327, in connect
    return _ConnectionFairy._checkout(self)
  File "/home/airflow/.local/lib/python3.8/site-packages/sqlalchemy/pool/base.py", line 894, in _checkout
    fairy = _ConnectionRecord.checkout(pool)
  File "/home/airflow/.local/lib/python3.8/site-packages/sqlalchemy/pool/base.py", line 493, in checkout
    rec = pool._do_get()
  File "/home/airflow/.local/lib/python3.8/site-packages/sqlalchemy/pool/impl.py", line 256, in _do_get
    return self._create_connection()
  File "/home/airflow/.local/lib/python3.8/site-packages/sqlalchemy/pool/base.py", line 273, in _create_connection
    return _ConnectionRecord(self)
  File "/home/airflow/.local/lib/python3.8/site-packages/sqlalchemy/pool/base.py", line 388, in __init__
    self.__connect()
  File "/home/airflow/.local/lib/python3.8/site-packages/sqlalchemy/pool/base.py", line 691, in __connect
    pool.logger.debug("Error on connect(): %s", e)
  File "/home/airflow/.local/lib/python3.8/site-packages/sqlalchemy/util/langhelpers.py", line 70, in __exit__
    compat.raise_(
  File "/home/airflow/.local/lib/python3.8/site-packages/sqlalchemy/util/compat.py", line 211, in raise_
    raise exception
  File "/home/airflow/.local/lib/python3.8/site-packages/sqlalchemy/pool/base.py", line 686, in __connect
    self.dbapi_connection = connection = pool._invoke_creator(self)
  File "/home/airflow/.local/lib/python3.8/site-packages/sqlalchemy/engine/create.py", line 574, in connect
    return dialect.connect(*cargs, **cparams)
  File "/home/airflow/.local/lib/python3.8/site-packages/sqlalchemy/engine/default.py", line 598, in connect
    return self.dbapi.connect(*cargs, **cparams)
  File "/home/airflow/.local/lib/python3.8/site-packages/psycopg2/__init__.py", line 122, in connect
    conn = _connect(dsn, connection_factory=connection_factory, **kwasync)
psycopg2.OperationalError: could not translate host name "postgres" to address: Temporary failure in name resolution


The above exception was the direct cause of the following exception:

Traceback (most recent call last):
  File "/home/airflow/.local/lib/python3.8/site-packages/airflow/jobs/job.py", line 190, in heartbeat
    session.merge(self)
  File "/home/airflow/.local/lib/python3.8/site-packages/sqlalchemy/orm/session.py", line 3056, in merge
    return self._merge(
  File "/home/airflow/.local/lib/python3.8/site-packages/sqlalchemy/orm/session.py", line 3136, in _merge
    merged = self.get(
  File "/home/airflow/.local/lib/python3.8/site-packages/sqlalchemy/orm/session.py", line 2853, in get
    return self._get_impl(
  File "/home/airflow/.local/lib/python3.8/site-packages/sqlalchemy/orm/session.py", line 2975, in _get_impl
    return db_load_fn(
  File "/home/airflow/.local/lib/python3.8/site-packages/sqlalchemy/orm/loading.py", line 530, in load_on_pk_identity
    session.execute(
  File "/home/airflow/.local/lib/python3.8/site-packages/sqlalchemy/orm/session.py", line 1716, in execute
    conn = self._connection_for_bind(bind)
  File "/home/airflow/.local/lib/python3.8/site-packages/sqlalchemy/orm/session.py", line 1555, in _connection_for_bind
    return self._transaction._connection_for_bind(
  File "/home/airflow/.local/lib/python3.8/site-packages/sqlalchemy/orm/session.py", line 750, in _connection_for_bind
    conn = bind.connect()
  File "/home/airflow/.local/lib/python3.8/site-packages/sqlalchemy/future/engine.py", line 406, in connect
    return super(Engine, self).connect()
  File "/home/airflow/.local/lib/python3.8/site-packages/sqlalchemy/engine/base.py", line 3325, in connect
    return self._connection_cls(self, close_with_result=close_with_result)
  File "/home/airflow/.local/lib/python3.8/site-packages/sqlalchemy/engine/base.py", line 96, in __init__
    else engine.raw_connection()
  File "/home/airflow/.local/lib/python3.8/site-packages/sqlalchemy/engine/base.py", line 3404, in raw_connection
    return self._wrap_pool_connect(self.pool.connect, _connection)
  File "/home/airflow/.local/lib/python3.8/site-packages/sqlalchemy/engine/base.py", line 3374, in _wrap_pool_connect
    Connection._handle_dbapi_exception_noconnection(
  File "/home/airflow/.local/lib/python3.8/site-packages/sqlalchemy/engine/base.py", line 2208, in _handle_dbapi_exception_noconnection
    util.raise_(
  File "/home/airflow/.local/lib/python3.8/site-packages/sqlalchemy/util/compat.py", line 211, in raise_
    raise exception
  File "/home/airflow/.local/lib/python3.8/site-packages/sqlalchemy/engine/base.py", line 3371, in _wrap_pool_connect
    return fn()
  File "/home/airflow/.local/lib/python3.8/site-packages/sqlalchemy/pool/base.py", line 327, in connect
    return _ConnectionFairy._checkout(self)
  File "/home/airflow/.local/lib/python3.8/site-packages/sqlalchemy/pool/base.py", line 894, in _checkout
    fairy = _ConnectionRecord.checkout(pool)
  File "/home/airflow/.local/lib/python3.8/site-packages/sqlalchemy/pool/base.py", line 493, in checkout
    rec = pool._do_get()
  File "/home/airflow/.local/lib/python3.8/site-packages/sqlalchemy/pool/impl.py", line 256, in _do_get
    return self._create_connection()
  File "/home/airflow/.local/lib/python3.8/site-packages/sqlalchemy/pool/base.py", line 273, in _create_connection
    return _ConnectionRecord(self)
  File "/home/airflow/.local/lib/python3.8/site-packages/sqlalchemy/pool/base.py", line 388, in __init__
    self.__connect()
  File "/home/airflow/.local/lib/python3.8/site-packages/sqlalchemy/pool/base.py", line 691, in __connect
    pool.logger.debug("Error on connect(): %s", e)
  File "/home/airflow/.local/lib/python3.8/site-packages/sqlalchemy/util/langhelpers.py", line 70, in __exit__
    compat.raise_(
  File "/home/airflow/.local/lib/python3.8/site-packages/sqlalchemy/util/compat.py", line 211, in raise_
    raise exception
  File "/home/airflow/.local/lib/python3.8/site-packages/sqlalchemy/pool/base.py", line 686, in __connect
    self.dbapi_connection = connection = pool._invoke_creator(self)
  File "/home/airflow/.local/lib/python3.8/site-packages/sqlalchemy/engine/create.py", line 574, in connect
    return dialect.connect(*cargs, **cparams)
  File "/home/airflow/.local/lib/python3.8/site-packages/sqlalchemy/engine/default.py", line 598, in connect
    return self.dbapi.connect(*cargs, **cparams)
  File "/home/airflow/.local/lib/python3.8/site-packages/psycopg2/__init__.py", line 122, in connect
    conn = _connect(dsn, connection_factory=connection_factory, **kwasync)
sqlalchemy.exc.OperationalError: (psycopg2.OperationalError) could not translate host name "postgres" to address: Temporary failure in name resolution

(Background on this error at: https://sqlalche.me/e/14/e3q8)
[2023-11-26T19:49:10.845+0000] {python.py:194} INFO - Done. Returned value was: None
[2023-11-26T19:49:10.858+0000] {taskinstance.py:1400} INFO - Marking task as SUCCESS. dag_id=outcomes_dag, task_id=transform, execution_date=20231120T000000, start_date=20231126T194813, end_date=20231126T194910
[2023-11-26T19:49:10.959+0000] {local_task_job_runner.py:228} INFO - Task exited with return code 0
[2023-11-26T19:49:10.986+0000] {taskinstance.py:2778} INFO - 1 downstream tasks scheduled from follow-on schedule check
