[2023-11-25T18:53:47.863+0000] {logging_mixin.py:154} INFO - Changing /opt/***/logs/dag_id=outcomes_dag/run_id=scheduled__2023-11-18T00:00:00+00:00/task_id=transform permission to 509
[2023-11-25T18:53:47.903+0000] {logging_mixin.py:154} INFO - Changing /opt/***/logs/dag_id=outcomes_dag/run_id=scheduled__2023-11-18T00:00:00+00:00/task_id=transform permission to 509
[2023-11-25T18:53:47.952+0000] {taskinstance.py:1159} INFO - Dependencies all met for dep_context=non-requeueable deps ti=<TaskInstance: outcomes_dag.transform scheduled__2023-11-18T00:00:00+00:00 [queued]>
[2023-11-25T18:53:47.971+0000] {taskinstance.py:1159} INFO - Dependencies all met for dep_context=requeueable deps ti=<TaskInstance: outcomes_dag.transform scheduled__2023-11-18T00:00:00+00:00 [queued]>
[2023-11-25T18:53:47.972+0000] {taskinstance.py:1361} INFO - Starting attempt 1 of 1
[2023-11-25T18:53:48.060+0000] {taskinstance.py:1382} INFO - Executing <Task(PythonOperator): transform> on 2023-11-18 00:00:00+00:00
[2023-11-25T18:53:48.071+0000] {standard_task_runner.py:57} INFO - Started process 416 to run task
[2023-11-25T18:53:48.074+0000] {standard_task_runner.py:84} INFO - Running: ['***', 'tasks', 'run', 'outcomes_dag', 'transform', 'scheduled__2023-11-18T00:00:00+00:00', '--job-id', '52', '--raw', '--subdir', 'DAGS_FOLDER/outcomes_dag.py', '--cfg-path', '/tmp/tmpch9fqky9']
[2023-11-25T18:53:48.078+0000] {standard_task_runner.py:85} INFO - Job 52: Subtask transform
[2023-11-25T18:53:48.136+0000] {logging_mixin.py:154} INFO - Changing /opt/***/logs/dag_id=outcomes_dag/run_id=scheduled__2023-11-18T00:00:00+00:00/task_id=transform permission to 509
[2023-11-25T18:53:48.139+0000] {task_command.py:416} INFO - Running <TaskInstance: outcomes_dag.transform scheduled__2023-11-18T00:00:00+00:00 [running]> on host 533b0beedf51
[2023-11-25T18:53:48.480+0000] {taskinstance.py:1662} INFO - Exporting env vars: AIRFLOW_CTX_DAG_OWNER='***' AIRFLOW_CTX_DAG_ID='outcomes_dag' AIRFLOW_CTX_TASK_ID='transform' AIRFLOW_CTX_EXECUTION_DATE='2023-11-18T00:00:00+00:00' AIRFLOW_CTX_TRY_NUMBER='1' AIRFLOW_CTX_DAG_RUN_ID='scheduled__2023-11-18T00:00:00+00:00'
[2023-11-25T18:53:48.897+0000] {logging_mixin.py:154} INFO - In function transform_data()
[2023-11-25T18:54:07.395+0000] {python.py:194} INFO - Done. Returned value was:        Animal ID   Name  ... Date of Outcome Years Age upon Outcome
0        A794011  Chunk  ...      2019-05-08                      2
1        A776359  Gizmo  ...      2018-07-18                      1
2        A821648    NaN  ...      2020-08-16                      1
3        A720371  Moose  ...      2016-02-13                      0
4        A674754    NaN  ...      2014-03-18                      0
...          ...    ...  ...             ...                    ...
157342   A889805  Louie  ...      2023-11-25                      1
157343   A890610  *Lars  ...      2023-11-20                      4
157344   A893305    NaN  ...      2023-11-26                      2
157345   A893306    NaN  ...      2023-11-26                     10
157346   A893123    NaN  ...      2023-11-26                      2

[157347 rows x 12 columns]
[2023-11-25T18:54:08.034+0000] {taskinstance.py:1400} INFO - Marking task as SUCCESS. dag_id=outcomes_dag, task_id=transform, execution_date=20231118T000000, start_date=20231125T185347, end_date=20231125T185408
[2023-11-25T18:54:08.101+0000] {local_task_job_runner.py:228} INFO - Task exited with return code 0
[2023-11-25T18:54:08.116+0000] {taskinstance.py:2778} INFO - 0 downstream tasks scheduled from follow-on schedule check
[2023-11-26T19:48:08.395+0000] {logging_mixin.py:154} INFO - Changing /opt/***/logs/dag_id=outcomes_dag/run_id=scheduled__2023-11-18T00:00:00+00:00/task_id=transform permission to 509
[2023-11-26T19:48:08.442+0000] {logging_mixin.py:154} INFO - Changing /opt/***/logs/dag_id=outcomes_dag/run_id=scheduled__2023-11-18T00:00:00+00:00/task_id=transform permission to 509
[2023-11-26T19:48:08.500+0000] {taskinstance.py:1159} INFO - Dependencies all met for dep_context=non-requeueable deps ti=<TaskInstance: outcomes_dag.transform scheduled__2023-11-18T00:00:00+00:00 [queued]>
[2023-11-26T19:48:08.518+0000] {taskinstance.py:1159} INFO - Dependencies all met for dep_context=requeueable deps ti=<TaskInstance: outcomes_dag.transform scheduled__2023-11-18T00:00:00+00:00 [queued]>
[2023-11-26T19:48:08.518+0000] {taskinstance.py:1361} INFO - Starting attempt 1 of 1
[2023-11-26T19:48:08.544+0000] {taskinstance.py:1382} INFO - Executing <Task(PythonOperator): transform> on 2023-11-18 00:00:00+00:00
[2023-11-26T19:48:08.552+0000] {standard_task_runner.py:57} INFO - Started process 688 to run task
[2023-11-26T19:48:08.556+0000] {standard_task_runner.py:84} INFO - Running: ['***', 'tasks', 'run', 'outcomes_dag', 'transform', 'scheduled__2023-11-18T00:00:00+00:00', '--job-id', '76', '--raw', '--subdir', 'DAGS_FOLDER/outcomes_dag.py', '--cfg-path', '/tmp/tmp9_j6ty6x']
[2023-11-26T19:48:08.559+0000] {standard_task_runner.py:85} INFO - Job 76: Subtask transform
[2023-11-26T19:48:08.627+0000] {logging_mixin.py:154} INFO - Changing /opt/***/logs/dag_id=outcomes_dag/run_id=scheduled__2023-11-18T00:00:00+00:00/task_id=transform permission to 509
[2023-11-26T19:48:08.631+0000] {task_command.py:416} INFO - Running <TaskInstance: outcomes_dag.transform scheduled__2023-11-18T00:00:00+00:00 [running]> on host a66846cad9d1
[2023-11-26T19:48:09.105+0000] {taskinstance.py:1662} INFO - Exporting env vars: AIRFLOW_CTX_DAG_OWNER='***' AIRFLOW_CTX_DAG_ID='outcomes_dag' AIRFLOW_CTX_TASK_ID='transform' AIRFLOW_CTX_EXECUTION_DATE='2023-11-18T00:00:00+00:00' AIRFLOW_CTX_TRY_NUMBER='1' AIRFLOW_CTX_DAG_RUN_ID='scheduled__2023-11-18T00:00:00+00:00'
[2023-11-26T19:48:09.988+0000] {logging_mixin.py:154} INFO - In function transform_data()
[2023-11-26T19:48:49.290+0000] {job.py:219} ERROR - Job heartbeat got an exception
Traceback (most recent call last):
  File "/home/airflow/.local/lib/python3.8/site-packages/sqlalchemy/engine/base.py", line 3371, in _wrap_pool_connect
    return fn()
  File "/home/airflow/.local/lib/python3.8/site-packages/sqlalchemy/pool/base.py", line 327, in connect
    return _ConnectionFairy._checkout(self)
  File "/home/airflow/.local/lib/python3.8/site-packages/sqlalchemy/pool/base.py", line 894, in _checkout
    fairy = _ConnectionRecord.checkout(pool)
  File "/home/airflow/.local/lib/python3.8/site-packages/sqlalchemy/pool/base.py", line 493, in checkout
    rec = pool._do_get()
  File "/home/airflow/.local/lib/python3.8/site-packages/sqlalchemy/pool/impl.py", line 256, in _do_get
    return self._create_connection()
  File "/home/airflow/.local/lib/python3.8/site-packages/sqlalchemy/pool/base.py", line 273, in _create_connection
    return _ConnectionRecord(self)
  File "/home/airflow/.local/lib/python3.8/site-packages/sqlalchemy/pool/base.py", line 388, in __init__
    self.__connect()
  File "/home/airflow/.local/lib/python3.8/site-packages/sqlalchemy/pool/base.py", line 691, in __connect
    pool.logger.debug("Error on connect(): %s", e)
  File "/home/airflow/.local/lib/python3.8/site-packages/sqlalchemy/util/langhelpers.py", line 70, in __exit__
    compat.raise_(
  File "/home/airflow/.local/lib/python3.8/site-packages/sqlalchemy/util/compat.py", line 211, in raise_
    raise exception
  File "/home/airflow/.local/lib/python3.8/site-packages/sqlalchemy/pool/base.py", line 686, in __connect
    self.dbapi_connection = connection = pool._invoke_creator(self)
  File "/home/airflow/.local/lib/python3.8/site-packages/sqlalchemy/engine/create.py", line 574, in connect
    return dialect.connect(*cargs, **cparams)
  File "/home/airflow/.local/lib/python3.8/site-packages/sqlalchemy/engine/default.py", line 598, in connect
    return self.dbapi.connect(*cargs, **cparams)
  File "/home/airflow/.local/lib/python3.8/site-packages/psycopg2/__init__.py", line 122, in connect
    conn = _connect(dsn, connection_factory=connection_factory, **kwasync)
psycopg2.OperationalError: could not translate host name "postgres" to address: Temporary failure in name resolution


The above exception was the direct cause of the following exception:

Traceback (most recent call last):
  File "/home/airflow/.local/lib/python3.8/site-packages/airflow/jobs/job.py", line 190, in heartbeat
    session.merge(self)
  File "/home/airflow/.local/lib/python3.8/site-packages/sqlalchemy/orm/session.py", line 3056, in merge
    return self._merge(
  File "/home/airflow/.local/lib/python3.8/site-packages/sqlalchemy/orm/session.py", line 3136, in _merge
    merged = self.get(
  File "/home/airflow/.local/lib/python3.8/site-packages/sqlalchemy/orm/session.py", line 2853, in get
    return self._get_impl(
  File "/home/airflow/.local/lib/python3.8/site-packages/sqlalchemy/orm/session.py", line 2975, in _get_impl
    return db_load_fn(
  File "/home/airflow/.local/lib/python3.8/site-packages/sqlalchemy/orm/loading.py", line 530, in load_on_pk_identity
    session.execute(
  File "/home/airflow/.local/lib/python3.8/site-packages/sqlalchemy/orm/session.py", line 1716, in execute
    conn = self._connection_for_bind(bind)
  File "/home/airflow/.local/lib/python3.8/site-packages/sqlalchemy/orm/session.py", line 1555, in _connection_for_bind
    return self._transaction._connection_for_bind(
  File "/home/airflow/.local/lib/python3.8/site-packages/sqlalchemy/orm/session.py", line 750, in _connection_for_bind
    conn = bind.connect()
  File "/home/airflow/.local/lib/python3.8/site-packages/sqlalchemy/future/engine.py", line 406, in connect
    return super(Engine, self).connect()
  File "/home/airflow/.local/lib/python3.8/site-packages/sqlalchemy/engine/base.py", line 3325, in connect
    return self._connection_cls(self, close_with_result=close_with_result)
  File "/home/airflow/.local/lib/python3.8/site-packages/sqlalchemy/engine/base.py", line 96, in __init__
    else engine.raw_connection()
  File "/home/airflow/.local/lib/python3.8/site-packages/sqlalchemy/engine/base.py", line 3404, in raw_connection
    return self._wrap_pool_connect(self.pool.connect, _connection)
  File "/home/airflow/.local/lib/python3.8/site-packages/sqlalchemy/engine/base.py", line 3374, in _wrap_pool_connect
    Connection._handle_dbapi_exception_noconnection(
  File "/home/airflow/.local/lib/python3.8/site-packages/sqlalchemy/engine/base.py", line 2208, in _handle_dbapi_exception_noconnection
    util.raise_(
  File "/home/airflow/.local/lib/python3.8/site-packages/sqlalchemy/util/compat.py", line 211, in raise_
    raise exception
  File "/home/airflow/.local/lib/python3.8/site-packages/sqlalchemy/engine/base.py", line 3371, in _wrap_pool_connect
    return fn()
  File "/home/airflow/.local/lib/python3.8/site-packages/sqlalchemy/pool/base.py", line 327, in connect
    return _ConnectionFairy._checkout(self)
  File "/home/airflow/.local/lib/python3.8/site-packages/sqlalchemy/pool/base.py", line 894, in _checkout
    fairy = _ConnectionRecord.checkout(pool)
  File "/home/airflow/.local/lib/python3.8/site-packages/sqlalchemy/pool/base.py", line 493, in checkout
    rec = pool._do_get()
  File "/home/airflow/.local/lib/python3.8/site-packages/sqlalchemy/pool/impl.py", line 256, in _do_get
    return self._create_connection()
  File "/home/airflow/.local/lib/python3.8/site-packages/sqlalchemy/pool/base.py", line 273, in _create_connection
    return _ConnectionRecord(self)
  File "/home/airflow/.local/lib/python3.8/site-packages/sqlalchemy/pool/base.py", line 388, in __init__
    self.__connect()
  File "/home/airflow/.local/lib/python3.8/site-packages/sqlalchemy/pool/base.py", line 691, in __connect
    pool.logger.debug("Error on connect(): %s", e)
  File "/home/airflow/.local/lib/python3.8/site-packages/sqlalchemy/util/langhelpers.py", line 70, in __exit__
    compat.raise_(
  File "/home/airflow/.local/lib/python3.8/site-packages/sqlalchemy/util/compat.py", line 211, in raise_
    raise exception
  File "/home/airflow/.local/lib/python3.8/site-packages/sqlalchemy/pool/base.py", line 686, in __connect
    self.dbapi_connection = connection = pool._invoke_creator(self)
  File "/home/airflow/.local/lib/python3.8/site-packages/sqlalchemy/engine/create.py", line 574, in connect
    return dialect.connect(*cargs, **cparams)
  File "/home/airflow/.local/lib/python3.8/site-packages/sqlalchemy/engine/default.py", line 598, in connect
    return self.dbapi.connect(*cargs, **cparams)
  File "/home/airflow/.local/lib/python3.8/site-packages/psycopg2/__init__.py", line 122, in connect
    conn = _connect(dsn, connection_factory=connection_factory, **kwasync)
sqlalchemy.exc.OperationalError: (psycopg2.OperationalError) could not translate host name "postgres" to address: Temporary failure in name resolution

(Background on this error at: https://sqlalche.me/e/14/e3q8)
[2023-11-26T19:49:06.311+0000] {python.py:194} INFO - Done. Returned value was: None
[2023-11-26T19:49:06.326+0000] {taskinstance.py:1400} INFO - Marking task as SUCCESS. dag_id=outcomes_dag, task_id=transform, execution_date=20231118T000000, start_date=20231126T194808, end_date=20231126T194906
[2023-11-26T19:49:06.450+0000] {local_task_job_runner.py:228} INFO - Task exited with return code 0
[2023-11-26T19:49:06.636+0000] {taskinstance.py:2778} INFO - 0 downstream tasks scheduled from follow-on schedule check
